<mujoco model="go2">
  <compiler angle="radian" meshdir="assets" autolimits="true" />

  <!-- <option cone="elliptic" impratio="100" /> -->
  <option timestep="0.02" iterations="1" ls_iterations="5">
    <flag eulerdamp="disable" />
  </option>
  <custom>
    <numeric data="15" name="max_contact_points" />
    <numeric data="15" name="max_geom_pairs" />
  </custom>

  <default>
    <geom condim="3" solimp="0.0 0.95 0.01" />
    <default class="go2">
      <site rgba="1 0 0 1" size="0.01" group="5" />
      <joint damping="0.005" armature="0.01" frictionloss="0.05" />
      <position kp="10" dampratio="0.3"/>
      <default class="abduction">
        <joint axis="1 0 0" range="-1.0472 1.0472"/>
      </default>
      <default class="hip">
        <joint axis="0 1 0"/>
        <default class="front_hip">
          <joint range="-1.5708 3.4907"/>
        </default>
        <default class="back_hip">
          <joint range="-0.5236 4.5379"/>
        </default>
      </default>
      <default class="knee">
        <joint axis="0 1 0" range="-2.8 -0.3"/>
      </default>
      <default class="visual">
        <geom type="mesh" contype="0" conaffinity="0" group="2" material="metal"/>
      </default>
      <default class="collision">
        <geom group="3" type="capsule" friction="0.4" margin="0.001"/>
        <default class="foot">
          <geom type="sphere" size="0.022" priority="1" condim="6" friction="0.6"/>
        </default>
      </default>
    </default>
  </default>

  <asset>
    <material name="black" rgba="0.2 0.2 0.2 1" />
    <material name="metal" rgba="0.7 0.7 0.7 1" />
    <material name="white" rgba="1 1 1 1" />
    <material name="gray" rgba="0.671705 0.692426 0.774270 1" />

    <mesh file="assets/base_0.obj" />
    <mesh file="assets/base_1.obj" />
    <mesh file="assets/base_2.obj" />
    <mesh file="assets/base_3.obj" />
    <mesh file="assets/base_4.obj" />
    <mesh file="assets/hip_0.obj" />
    <mesh file="assets/hip_1.obj" />
    <mesh file="assets/thigh_0.obj" />
    <mesh file="assets/thigh_1.obj" />
    <mesh file="assets/thigh_mirror_0.obj" />
    <mesh file="assets/thigh_mirror_1.obj" />
    <mesh file="assets/calf_0.obj" />
    <mesh file="assets/calf_1.obj" />
    <mesh file="assets/calf_mirror_0.obj" />
    <mesh file="assets/calf_mirror_1.obj" />
    <mesh file="assets/foot.obj" />
  </asset>

  <worldbody>
    <light pos="1 0 3.5" dir="0 0 -1" directional="true" />
    <body name="base_link" pos="0 0 0.445" childclass="go2">
      <inertial pos="0.021112 0 -0.005366" quat="-0.000543471 0.713435 -0.00173769 0.700719"
        mass="6.921"
        diaginertia="0.107027 0.0980771 0.0244531" />
      <freejoint name="floating_base_joint" />
      <geom mesh="base_0" material="black" class="visual" />
      <geom mesh="base_1" material="black" class="visual" />
      <geom mesh="base_2" material="black" class="visual" />
      <geom mesh="base_3" material="white" class="visual" />
      <geom mesh="base_4" material="gray" class="visual" />
      <geom size="0.06 0.14" pos="-0.02 0 0" class="collision" quat="0.707107 0 0.707107 0" />
      <geom size="0.06 0.03" pos="0.2 0 -0.015" class="collision" />
      <site name="imu" pos="-0.02557 0 0.04232" />
      <body name="FL_hip" pos="0.1934 0.0465 0">
        <inertial pos="-0.0054 0.00194 -0.000105" quat="0.497014 0.499245 0.505462 0.498237"
          mass="0.678"
          diaginertia="0.00088403 0.000596003 0.000479967" />
        <joint name="FL_hip_joint" class="abduction" actuatorfrcrange="-88 88" />
        <geom mesh="hip_0" material="metal" class="visual" />
        <geom mesh="hip_1" material="gray" class="visual" />
        <geom size="0.03 0.015" pos="0 0.08 0" quat="0.707107 0.707107 0 0" class="collision" />
        <body name="FL_thigh" pos="0 0.0955 0">
          <inertial pos="-0.00374 -0.0223 -0.0327" quat="0.829533 0.0847635 -0.0200632 0.551623"
            mass="1.152"
            diaginertia="0.00594973 0.00584149 0.000878787" />
          <joint name="FL_thigh_joint" class="front_hip" actuatorfrcrange="-139 139" />
          <geom mesh="thigh_0" material="metal" class="visual" />
          <geom mesh="thigh_1" material="gray" class="visual" />
          <geom size="0.02 0.07" pos="-0.01 -0.01 -0.13" class="collision" />
          <body name="FL_calf" pos="0 0 -0.213">
            <inertial pos="0.00629595 -0.000622121 -0.141417"
              quat="0.710672 0.00154099 -0.00450087 0.703508"
              mass="0.241352" diaginertia="0.0014901 0.00146356 5.31397e-05" />
            <joint name="FL_calf_joint" class="knee" actuatorfrcrange="-139 139" />
            <geom mesh="calf_0" material="gray" class="visual" />
            <geom mesh="calf_1" material="black" class="visual" />
            <geom size="0.007 0.08" pos="0.01 0 -0.1" quat="1 0 0 0"
              class="collision" />
            <geom pos="0 0 -0.213" mesh="foot" class="visual" material="black" />
            <body name="FL_foot" pos="0 0 -0.213">
              <geom class="foot" pos="-0.002 0 0" name="FL_foot_collision" />
              <inertial diaginertia="1e-14 1e-14 1e-14" mass="1e-6" pos="0 0 0"/>
              <site name="FL_grf_sensor" pos="0 0 0" size="0.025" type="sphere"/>
            </body>
          </body>
        </body>
      </body>
      <body name="FR_hip" pos="0.1934 -0.0465 0">
        <inertial pos="-0.0054 -0.00194 -0.000105" quat="0.498237 0.505462 0.499245 0.497014"
          mass="0.678"
          diaginertia="0.00088403 0.000596003 0.000479967" />
        <joint name="FR_hip_joint" class="abduction" actuatorfrcrange="-88 88" />
        <geom mesh="hip_0" material="metal" class="visual" quat="4.63268e-05 1 0 0" />
        <geom mesh="hip_1" material="gray" class="visual" quat="4.63268e-05 1 0 0" />
        <geom size="0.03 0.015" pos="0 -0.08 0" quat="0.707107 0.707107 0 0" class="collision" />
        <body name="FR_thigh" pos="0 -0.0955 0">
          <inertial pos="-0.00374 0.0223 -0.0327" quat="0.551623 -0.0200632 0.0847635 0.829533"
            mass="1.152"
            diaginertia="0.00594973 0.00584149 0.000878787" />
          <joint name="FR_thigh_joint" class="front_hip" actuatorfrcrange="-139 139" />
          <geom mesh="thigh_mirror_0" material="metal" class="visual" />
          <geom mesh="thigh_mirror_1" material="gray" class="visual" />
          <geom size="0.02 0.07" pos="-0.01 0.01 -0.13" class="collision" />
          <body name="FR_calf" pos="0 0 -0.213">
            <inertial pos="0.00629595 0.000622121 -0.141417"
              quat="0.703508 -0.00450087 0.00154099 0.710672"
              mass="0.241352" diaginertia="0.0014901 0.00146356 5.31397e-05" />
            <joint name="FR_calf_joint" class="knee" actuatorfrcrange="-139 139" />
            <geom mesh="calf_mirror_0" material="gray" class="visual" />
            <geom mesh="calf_mirror_1" material="black" class="visual" />
            <geom size="0.007 0.08" pos="0.01 0 -0.1" quat="1 0 0 0"
              class="collision" />
            <geom pos="0 0 -0.213" mesh="foot" class="visual" material="black" />
            <body name="FR_foot" pos="0 0 -0.213">
              <geom class="foot" pos="-0.002 0 0" name="FR_foot_collision" />
              <inertial diaginertia="1e-14 1e-14 1e-14" mass="1e-6" pos="0 0 0"/>
              <site name="FR_grf_sensor" pos="0 0 0" size="0.025" type="sphere"/>
            </body>
          </body>
        </body>
      </body>
      <body name="RL_hip" pos="-0.1934 0.0465 0">
        <inertial pos="0.0054 0.00194 -0.000105" quat="0.505462 0.498237 0.497014 0.499245"
          mass="0.678"
          diaginertia="0.00088403 0.000596003 0.000479967" />
        <joint name="RL_hip_joint" class="abduction" actuatorfrcrange="-88 88" />
        <geom mesh="hip_0" material="metal" class="visual" quat="4.63268e-05 0 1 0" />
        <geom mesh="hip_1" material="gray" class="visual" quat="4.63268e-05 0 1 0" />
        <geom size="0.03 0.015" pos="0 0.08 0" quat="0.707107 0.707107 0 0" class="collision" />
        <body name="RL_thigh" pos="0 0.0955 0">
          <inertial pos="-0.00374 -0.0223 -0.0327" quat="0.829533 0.0847635 -0.0200632 0.551623"
            mass="1.152"
            diaginertia="0.00594973 0.00584149 0.000878787" />
          <joint name="RL_thigh_joint" class="back_hip" actuatorfrcrange="-160 160" />
          <geom mesh="thigh_0" material="metal" class="visual" />
          <geom mesh="thigh_1" material="gray" class="visual" />
          <geom size="0.02 0.07" pos="-0.01 -0.01 -0.13"
            class="collision" />
          <body name="RL_calf" pos="0 0 -0.213">
            <inertial pos="0.00629595 -0.000622121 -0.141417"
              quat="0.710672 0.00154099 -0.00450087 0.703508"
              mass="0.241352" diaginertia="0.0014901 0.00146356 5.31397e-05" />
            <joint name="RL_calf_joint" class="knee" actuatorfrcrange="-160 160" />
            <geom mesh="calf_0" material="gray" class="visual" />
            <geom mesh="calf_1" material="black" class="visual" />
            <geom size="0.007 0.08" pos="0.01 0 -0.1" quat="1 0 0 0"
              class="collision" />
            <geom pos="0 0 -0.213" mesh="foot" class="visual" material="black" />
            <body name="RL_foot" pos="0 0 -0.213">
              <geom class="foot" pos="-0.002 0 0" name="RL_foot_collision" />
              <inertial diaginertia="1e-14 1e-14 1e-14" mass="1e-6" pos="0 0 0"/>
              <site name="RL_grf_sensor" pos="0 0 0" size="0.025" type="sphere"/>
            </body>
          </body>
        </body>
      </body>
      <body name="RR_hip" pos="-0.1934 -0.0465 0">
        <inertial pos="0.0054 -0.00194 -0.000105" quat="0.499245 0.497014 0.498237 0.505462"
          mass="0.678"
          diaginertia="0.00088403 0.000596003 0.000479967" />
        <joint name="RR_hip_joint" class="abduction" actuatorfrcrange="-88 88" />
        <geom mesh="hip_0" material="metal" class="visual"
          quat="2.14617e-09 4.63268e-05 4.63268e-05 -1" />
        <geom mesh="hip_1" material="gray" class="visual"
          quat="2.14617e-09 4.63268e-05 4.63268e-05 -1" />
        <geom size="0.03 0.015" pos="0 -0.08 0" quat="0.707107 0.707107 0 0" class="collision" />
        <body name="RR_thigh" pos="0 -0.0955 0">
          <inertial pos="-0.00374 0.0223 -0.0327" quat="0.551623 -0.0200632 0.0847635 0.829533"
            mass="1.152"
            diaginertia="0.00594973 0.00584149 0.000878787" />
          <joint name="RR_thigh_joint" class="back_hip" actuatorfrcrange="-160 160" />
          <geom mesh="thigh_mirror_0" material="metal" class="visual" />
          <geom mesh="thigh_mirror_1" material="gray" class="visual" />
          <geom size="0.02 0.07" pos="-0.01 0.01 -0.13"
            class="collision" />
          <body name="RR_calf" pos="0 0 -0.213">
            <inertial pos="0.00629595 0.000622121 -0.141417"
              quat="0.703508 -0.00450087 0.00154099 0.710672"
              mass="0.241352" diaginertia="0.0014901 0.00146356 5.31397e-05" />
            <joint name="RR_calf_joint" class="knee" actuatorfrcrange="-160 160" />
            <geom mesh="calf_mirror_0" material="gray" class="visual" />
            <geom mesh="calf_mirror_1" material="black" class="visual" />
            <geom size="0.007 0.08" pos="0.01 0 -0.1" quat="1 0 0 0"
              class="collision" />
            <geom pos="0 0 -0.213" mesh="foot" class="visual" material="black" />
            <body name="RR_foot" pos="-0.002 0 -0.213">
              <geom class="foot" pos="-0.002 0 0" name="RR_foot_collision" />
              <inertial diaginertia="1e-14 1e-14 1e-14" mass="1e-6" pos="0 0 0"/>
              <site name="RR_grf_sensor" pos="0 0 0" size="0.025" type="sphere"/>
            </body>
          </body>
        </body>
      </body>
    </body>
  </worldbody>

  <actuator>
    <!-- <position class="abduction" name="FR_hip" joint="FR_hip_joint" />
    <position class="hip" name="FR_thigh" joint="FR_thigh_joint" />
    <position class="knee" name="FR_calf" joint="FR_calf_joint" />
    <position class="abduction" name="FL_hip" joint="FL_hip_joint" />
    <position class="hip" name="FL_thigh" joint="FL_thigh_joint" />
    <position class="knee" name="FL_calf" joint="FL_calf_joint" />
    <position class="abduction" name="RR_hip" joint="RR_hip_joint" />
    <position class="hip" name="RR_thigh" joint="RR_thigh_joint" />
    <position class="knee" name="RR_calf" joint="RR_calf_joint" />
    <position class="abduction" name="RL_hip" joint="RL_hip_joint" />
    <position class="hip" name="RL_thigh" joint="RL_thigh_joint" />
    <position class="knee" name="RL_calf" joint="RL_calf_joint" /> -->
    <motor class="abduction" name="FR_hip" joint="FR_hip_joint" />
    <motor class="hip" name="FR_thigh" joint="FR_thigh_joint" />
    <motor class="knee" name="FR_calf" joint="FR_calf_joint" />
    <motor class="abduction" name="FL_hip" joint="FL_hip_joint" />
    <motor class="hip" name="FL_thigh" joint="FL_thigh_joint" />
    <motor class="knee" name="FL_calf" joint="FL_calf_joint" />
    <motor class="abduction" name="RR_hip" joint="RR_hip_joint" />
    <motor class="hip" name="RR_thigh" joint="RR_thigh_joint" />
    <motor class="knee" name="RR_calf" joint="RR_calf_joint" />
    <motor class="abduction" name="RL_hip" joint="RL_hip_joint" />
    <motor class="hip" name="RL_thigh" joint="RL_thigh_joint" />
    <motor class="knee" name="RL_calf" joint="RL_calf_joint" />
  </actuator>

  <sensor>
    <!--keep the order of the sensors for reading
      FR -> FL -> RR -> RL-->
    <jointpos name="FR_hip_pos" joint="FR_hip_joint" />
    <jointpos name="FR_thigh_pos" joint="FR_thigh_joint" />
    <jointpos name="FR_calf_pos" joint="FR_calf_joint" />
    <jointpos name="FL_hip_pos" joint="FL_hip_joint" />
    <jointpos name="FL_thigh_pos" joint="FL_thigh_joint" />
    <jointpos name="FL_calf_pos" joint="FL_calf_joint" />
    <jointpos name="RR_hip_pos" joint="RR_hip_joint" />
    <jointpos name="RR_thigh_pos" joint="RR_thigh_joint" />
    <jointpos name="RR_calf_pos" joint="RR_calf_joint" />
    <jointpos name="RL_hip_pos" joint="RL_hip_joint" />
    <jointpos name="RL_thigh_pos" joint="RL_thigh_joint" />
    <jointpos name="RL_calf_pos" joint="RL_calf_joint" />

    <jointvel name="FR_hip_vel" joint="FR_hip_joint" />
    <jointvel name="FR_thigh_vel" joint="FR_thigh_joint" />
    <jointvel name="FR_calf_vel" joint="FR_calf_joint" />
    <jointvel name="FL_hip_vel" joint="FL_hip_joint" />
    <jointvel name="FL_thigh_vel" joint="FL_thigh_joint" />
    <jointvel name="FL_calf_vel" joint="FL_calf_joint" />
    <jointvel name="RR_hip_vel" joint="RR_hip_joint" />
    <jointvel name="RR_thigh_vel" joint="RR_thigh_joint" />
    <jointvel name="RR_calf_vel" joint="RR_calf_joint" />
    <jointvel name="RL_hip_vel" joint="RL_hip_joint" />
    <jointvel name="RL_thigh_vel" joint="RL_thigh_joint" />
    <jointvel name="RL_calf_vel" joint="RL_calf_joint" />

    <jointactuatorfrc name="FR_hip_torque" joint="FR_hip_joint" noise="0.01" />
    <jointactuatorfrc name="FR_thigh_torque" joint="FR_thigh_joint" noise="0.01" />
    <jointactuatorfrc name="FR_calf_torque" joint="FR_calf_joint" noise="0.01" />
    <jointactuatorfrc name="FL_hip_torque" joint="FL_hip_joint" noise="0.01" />
    <jointactuatorfrc name="FL_thigh_torque" joint="FL_thigh_joint" noise="0.01" />
    <jointactuatorfrc name="FL_calf_torque" joint="FL_calf_joint" noise="0.01" />
    <jointactuatorfrc name="RR_hip_torque" joint="RR_hip_joint" noise="0.01" />
    <jointactuatorfrc name="RR_thigh_torque" joint="RR_thigh_joint" noise="0.01" />
    <jointactuatorfrc name="RR_calf_torque" joint="RR_calf_joint" noise="0.01" />
    <jointactuatorfrc name="RL_hip_torque" joint="RL_hip_joint" noise="0.01" />
    <jointactuatorfrc name="RL_thigh_torque" joint="RL_thigh_joint" noise="0.01" />
    <jointactuatorfrc name="RL_calf_torque" joint="RL_calf_joint" noise="0.01" />

    <framequat name="imu_quat" objtype="site" objname="imu" />
    <gyro name="imu_gyro" site="imu" />
    <accelerometer name="imu_acc" site="imu" />
    <!--keep the relative order between these four sensors-->
    <touch name="FR_contact_sensor" site="FR_grf_sensor"/>
    <touch name="FL_contact_sensor" site="FL_grf_sensor"/>
    <touch name="RR_contact_sensor" site="RR_grf_sensor"/>
    <touch name="RL_contact_sensor" site="RL_grf_sensor"/>
    
    <!-- Ground Truth -->
    <framepos name="frame_pos" objtype="site" objname="imu" />
    <velocimeter name="frame_vel" site="imu"/>
    <framelinvel name="frame_vel_global" objtype="site" objname="imu"/>
    <!--keep the relative order between these four sensors-->
    <force name="FR_grf" site="FR_grf_sensor"/>
    <force name="FL_grf" site="FL_grf_sensor"/>
    <force name="RR_grf" site="RR_grf_sensor"/>
    <force name="RL_grf" site="RL_grf_sensor"/>
    <framequat name="FR_foot_quat" objname="FR_grf_sensor" objtype="site"/>
    <framequat name="FL_foot_quat" objname="FL_grf_sensor" objtype="site"/>
    <framequat name="RR_foot_quat" objname="RR_grf_sensor" objtype="site"/>
    <framequat name="RL_foot_quat" objname="RL_grf_sensor" objtype="site"/>
  
  </sensor>

  <keyframe>
    <key name="stand" qpos="0 0 0.30 1 0 0 0 0 0.9 -1.8 0 0.9 -1.8 0 0.9 -1.8 0 0.9 -1.8"
      ctrl="0 0.9 -1.8 0 0.9 -1.8 0 0.9 -1.8 0 0.9 -1.8" />
  </keyframe>

  <!-- <contact>
    <exclude body1="base_link" body2="FL_hip"/>
    <exclude body1="base_link" body2="FR_hip"/>
    <exclude body1="base_link" body2="RL_hip"/>
    <exclude body1="base_link" body2="RR_hip"/>
    
    <exclude body1="FL_hip" body2="FL_thigh"/>
    <exclude body1="FR_hip" body2="FR_thigh"/>
    <exclude body1="RL_hip" body2="RL_thigh"/>
    <exclude body1="RR_hip" body2="RR_thigh"/>
    
    <exclude body1="FL_thigh" body2="FL_calf"/>
    <exclude body1="FR_thigh" body2="FR_calf"/>
    <exclude body1="RL_thigh" body2="RL_calf"/>
    <exclude body1="RR_thigh" body2="RR_calf"/>

    <exclude body1="FL_calf" body2="FL_foot"/>
    <exclude body1="FR_calf" body2="FR_foot"/>
    <exclude body1="RL_calf" body2="RL_foot"/>
    <exclude body1="RR_calf" body2="RR_foot"/>
  </contact> -->
</mujoco>